Workbook

Sheet Premissas
A1: IMPACTO — modelo de 120 meses (análise v0.30.0). Edite as colunas C–E; tudo nas abas mensais recalcula. Nada aqui altera o produto.
A2: Natureza: FATO = está no repositório · HIPÓTESE DO PROPRIETÁRIO = já declarada no repositório · PREMISSA DE MERCADO = não verificada, editável · DERIVADO = cálculo
A4: chave | B4: premissa | C4: Conservador | D4: Base | E4: Agressivo | F4: natureza | G4: fonte
A5: service_bps | B5: Taxa de serviço (bps) | C5: 350 | D5: 350 | E5: 350 | F5: FATO | G5: config/economic_model.json · monetization_rules (contract.platform_service_fee, INATIVA)
A6: authorship_bps | B6: Participação de autoria (bps) — NÃO é receita | C6: 150 | D6: 150 | E6: 150 | F6: FATO | G6: config/economic_model.json · ADR-337
A7: ai_pack_price_per_credit_cents | B7: Preço por crédito de IA (centavos) — hipótese de teste | C7: 10 | D7: 10 | E7: 10 | F7: HIPÓTESE DO PROPRIETÁRIO | G7: ai_credit_packs (pack.100 = R$ 10,00 / 100)
A8: pix_fee_pct | B8: Taxa de pagamento (PIX) % | C8: 1 | D8: 1 | E8: 1 | F8: HIPÓTESE DO PROPRIETÁRIO | G8: config/ai_economics.json pix_fee_pct_hypothesis
A9: tax_pct | B9: Tributos sobre receita % (hipótese) | C9: 8.65 | D9: 8.65 | E9: 8.65 | F9: HIPÓTESE DO PROPRIETÁRIO | G9: config/ai_economics.json tax_pct_hypothesis (não é parecer)
A10: support_cents_user_month | B10: Suporte por usuário ativo/mês (centavos) | C10: 30 | D10: 30 | E10: 30 | F10: HIPÓTESE DO PROPRIETÁRIO | G10: config/ai_economics.json
A11: ai_infra_cents_op | B11: Infra de IA por operação (centavos, motor local) | C11: 2 | D11: 2 | E11: 2 | F11: HIPÓTESE DO PROPRIETÁRIO | G11: config/ai_economics.json infra_cents_per_operation_hypothesis.local
A12: new_funders_month | B12: Novos financiadores por mês (operacional) | C12: 3 | D12: 3 | E12: 3 | F12: HIPÓTESE DO PROPRIETÁRIO | G12: config/economic_model.json new_funding_clients_per_month = 3 em todos os cenários
A13: ops_per_funder_year | B13: Operações por financiador por ano | C13: 1 | D13: 2 | E13: 3 | F13: HIPÓTESE DO PROPRIETÁRIO | G13: config/economic_model.json scenarios
A14: avg_op_cents | B14: Ticket médio financiado (centavos) | C14: 5000000 | D14: 15000000 | E14: 50000000 | F14: HIPÓTESE DO PROPRIETÁRIO | G14: config/economic_model.json scenarios
A15: settled_share | B15: Fração das operações que chega à quitação | C15: 0.6 | D15: 0.75 | E15: 0.85 | F15: HIPÓTESE DO PROPRIETÁRIO | G15: config/economic_model.json scenarios
A16: months_to_settle | B16: Meses até quitar | C16: 6 | D16: 5 | E16: 4 | F16: HIPÓTESE DO PROPRIETÁRIO | G16: config/economic_model.json scenarios
... A40: initial_cash_cents | B40: Caixa inicial (centavos) | C40: 0 | D40: 0 | E40: 0 | F40: PREMISSA DE MERCADO | G40: não informado pelo proprietário — zero por padrão
A42: — VALUATION (premissas de mercado; fontes no relatório) —
A43: saas_multiple | B43: Múltiplo sobre ARR de software (×) | C43: 2.5 | D43: 4 | E43: 6 | F43: PREMISSA DE MERCADO | G43: SEG 2Q26: público mediana 3,2×; M&A privado mediana 4,0×, média 6,2×; SaaS Capital 4,8–5,3× (modelado)
A44: txn_multiple | B44: Múltiplo sobre receita líquida transacional (×) | C44: 1.5 | D44: 2.3 | E44: 4 | F44: PREMISSA DE MERCADO | G44: Aventis 2025: marketplaces públicos mediana EV/Receita 2,3×; média histórica 5,6×
A45: services_multiple | B45: Múltiplo sobre receita de serviços (×) | C45: 1 | D45: 1.5 | E45: 2 | F45: PREMISSA DE MERCADO | G45: receita não recorrente; desconto forte
A46: ebitda_multiple | B46: Múltiplo EV/EBITDA (só quando EBITDA > 0, cruzamento) | C46: 8 | D46: 12 | E46: 15 | F46: PREMISSA DE MERCADO | G46: Aventis 2025: marketplaces públicos mediana 18×; privado menor
A47: discount_pct | B47: Desconto por concentração, risco regulatório, iliquidez e dependência do fundador % | C47: 45 | D47: 35 | E47: 25 | F47: PREMISSA DE MERCADO | G47: julgamento; editável
A48: usd_brl | B48: Câmbio US$/R$ (só para a meta em US$) | C48: 5.5 | D48: 5.5 | E48: 5.5 | F48: PREMISSA DE MERCADO | G48: não cotado
A50: — DILUIÇÃO DO FUNDADOR (mês, participação após a rodada) —
A51: dil_0 | B51: participação do fundador a partir do mês 0 | C51: 1 | D51: 1 | E51: 1 | F51: PREMISSA DE MERCADO | G51: editável
A52: dil_12 | B52: participação do fundador a partir do mês 12 | C52: 0.85 | D52: 0.85 | E52: 0.85 | F52: PREMISSA DE MERCADO | G52: editável
A53: dil_24 | B53: participação do fundador a partir do mês 24 | C53: 0.7 | D53: 0.7 | E53: 0.7 | F53: PREMISSA DE MERCADO | G53: editável
A54: dil_48 | B54: participação do fundador a partir do mês 48 | C54: 0.55 | D54: 0.55 | E54: 0.55 | F54: PREMISSA DE MERCADO | G54: editável
A55: dil_120 | B55: participação do fundador a partir do mês 120 | C55: 0.45 | D55: 0.45 | E55: 0.45 | F55: PREMISSA DE MERCADO | G55: editável

Sheet Cons-Atual
A1: Cenário conservador · desenho Atual (0 = sem contratos institucionais; 1 = com) · valores em CENTAVOS · fórmulas abertas
A2: hybrid | B2: 0
A3: Mês | B3: Financiadores ativos | C3: Contratos inst. ativos | D3: Novos contratos inst. | E3: OSCs ativas | F3: Operações | G3: GMV originado | H3: GMV quitado | I3: Participação de autoria (não é receita) | J3: Taxa registrada | K3: Taxa reconhecida (quitação, regra ativa) | L3: MRR software | M3: Implantação reconhecida | N3: Serviços | O3: RECEITA RECONHECIDA | P3: Faturado | Q3: Recebido (após inadimplência) | R3: COGS | S3: Margem bruta | T3: Tributos | U3: Pessoal | V3: Marketing+CAC | W3: Admin | X3: Margem de contribuição | Y3: EBITDA | Z3: Fluxo de caixa | AA3: Caixa acumulado | AB3: FTE | AC3: Contratos faturados no mês (novos + renovações anuais)
A4: 1 | B4: =0*(1-Premissas!$C$18/12)+Premissas!$C$12 | C4: =IF($B$2=1,0*(1-Premissas!$C$26/12)+D4,0) | D4: =IF(AND($B$2=1,A4>=Premissas!$C$23),Premissas!$C$22,0) | E4: =B4*Premissas!$C$28 | F4: =B4*Premissas!$C$13/12*MIN(1,A4/Premissas!$C$17) | G4: =F4*Premissas!$C$14 | H4: =IF(IF(A4-1-Premissas!$C$16>=0,OFFSET($J$4,A4-1-Premissas!$C$16,0),0)>0,ROUND(IF(A4-1-Premissas!$C$16>=0,OFFSET($J$4,A4-1-Premissas!$C$16,0),0)*10000/Premissas!$C$5*Premissas!$C$15,0),0) | I4: =ROUND(G4*Premissas!$C$6/10000,0) | J4: =ROUND(G4*Premissas!$C$5/10000,0) | K4: =IF(IF(A4-1-Premissas!$C$16>=0,OFFSET($A$4,A4-1-Premissas!$C$16,0)>=Premissas!$C$19,FALSE),ROUND(IF(A4-1-Premissas!$C$16>=0,OFFSET($J$4,A4-1-Premissas!$C$16,0),0)*Premissas!$C$15,0),0) | L4: =ROUND(C4*Premissas!$C$24/12,0) | M4: =ROUND(D4*Premissas!$C$25,0) | N4: =ROUND(E4*Premissas!$C$29+B4*Premissas!$C$30,0) | O4: =K4+L4+M4+N4 | P4: =K4+ROUND(AC4*Premissas!$C$24,0)+M4+N4 | Q4: =ROUND(IF(A4-1-Premissas!$C$21>=0,OFFSET($P$4,A4-1-Premissas!$C$21,0),0)*(1-Premissas!$C$20/100),0) | R4: =ROUND(F4*Premissas!$C$11+N4*Premissas!$C$31/100,0)+ROUND((E4+B4)*Premissas!$C$10,0)+ROUND(Q4*Premissas!$C$8/100,0)+ROUND(Premissas!$C$35+(B4+C4)*Premissas!$C$36,0) | S4: =O4-R4 | T4: =ROUND(O4*Premissas!$C$9/100,0) | U4: =ROUND(AB4*Premissas!$C$33,0) | V4: =Premissas!$C$37+ROUND(Premissas!$C$12*Premissas!$C$38+D4*Premissas!$C$27,0) | W4: =Premissas!$C$39 | X4: =S4-T4-ROUND(Premissas!$C$12*Premissas!$C$38+D4*Premissas!$C$27,0) | Y4: =O4-R4-T4-U4-V4-W4 | Z4: =Q4-R4-T4-U4-V4-W4 | AA4: =Premissas!$C$40+Z4 | AB4: =Premissas!$C$32+(B4+C4)/Premissas!$C$34 | AC4: =D4
A5: 2 | B5: =B4*(1-Premissas!$C$18/12)+Premissas!$C$12 | C5: =IF($B$2=1,C4*(1-Premissas!$C$26/12)+D5,0) | D5: =IF(AND($B$2=1,A5>=Premissas!$C$23),Premissas!$C$22,0) | E5: =B5*Premissas!$C$28 | F5: =B5*Premissas!$C$13/12*MIN(1,A5/Premissas!$C$17) | G5: =F5*Premissas!$C$14 | H5: =IF(IF(A5-1-Premissas!$C$16>=0,OFFSET($J$4,A5-1-Premissas!$C$16,0),0)>0,ROUND(IF(A5-1-Premissas!$C$16>=0,OFFSET($J$4,A5-1-Premissas!$C$16,0),0)*10000/Premissas!$C$5*Premissas!$C$15,0),0) | I5: =ROUND(G5*Premissas!$C$6/10000,0) | J5: =ROUND(G5*Premissas!$C$5/10000,0) | K5: =IF(IF(A5-1-Premissas!$C$16>=0,OFFSET($A$4,A5-1-Premissas!$C$16,0)>=Premissas!$C$19,FALSE),ROUND(IF(A5-1-Premissas!$C$16>=0,OFFSET($J$4,A5-1-Premissas!$C$16,0),0)*Premissas!$C$15,0),0) | L5: =ROUND(C5*Premissas!$C$24/12,0) | M5: =ROUND(D5*Premissas!$C$25,0) | N5: =ROUND(E5*Premissas!$C$29+B5*Premissas!$C$30,0) | O5: =K5+L5+M5+N5 | P5: =K5+ROUND(AC5*Premissas!$C$24,0)+M5+N5 | Q5: =ROUND(IF(A5-1-Premissas!$C$21>=0,OFFSET($P$4,A5-1-Premissas!$C$21,0),0)*(1-Premissas!$C$20/100),0) | R5: =ROUND(F5*Premissas!$C$11+N5*Premissas!$C$31/100,0)+ROUND((E5+B5)*Premissas!$C$10,0)+ROUND(Q5*Premissas!$C$8/100,0)+ROUND(Premissas!$C$35+(B5+C5)*Premissas!$C$36,0) | S5: =O5-R5 | T5: =ROUND(O5*Premissas!$C$9/100,0) | U5: =ROUND(AB5*Premissas!$C$33,0) | V5: =Premissas!$C$37+ROUND(Premissas!$C$12*Premissas!$C$38+D5*Premissas!$C$27,0) | W5: =Premissas!$C$39 | X5: =S5-T5-ROUND(Premissas!$C$12*Premissas!$C$38+D5*Premissas!$C$27,0) | Y5: =O5-R5-T5-U5-V5-W5 | Z5: =Q5-R5-T5-U5-V5-W5 | AA5: =AA4+Z5 | AB5: =Premissas!$C$32+(B5+C5)/Premissas!$C$34 | AC5: =D5
A6: 3 | B6: =B5*(1-Premissas!$C$18/12)+Premissas!$C$12 | C6: =IF($B$2=1,C5*(1-Premissas!$C$26/12)+D6,0) | D6: =IF(AND($B$2=1,A6>=Premissas!$C$23),Premissas!$C$22,0) | E6: =B6*Premissas!$C$28 | F6: =B6*Premissas!$C$13/12*MIN(1,A6/Premissas!$C$17) | G6: =F6*Premissas!$C$14 | H6: =IF(IF(A6-1-Premissas!$C$16>=0,OFFSET($J$4,A6-1-Premissas!$C$16,0),0)>0,ROUND(IF(A6-1-Premissas!$C$16>=0,OFFSET($J$4,A6-1-Premissas!$C$16,0),0)*10000/Premissas!$C$5*Premissas!$C$15,0),0) | I6: =ROUND(G6*Premissas!$C$6/10000,0) | J6: =ROUND(G6*Premissas!$C$5/10000,0) | K6: =IF(IF(A6-1-Premissas!$C$16>=0,OFFSET($A$4,A6-1-Premissas!$C$16,0)>=Premissas!$C$19,FALSE),ROUND(IF(A6-1-Premissas!$C$16>=0,OFFSET($J$4,A6-1-Premissas!$C$16,0),0)*Premissas!$C$15,0),0) | L6: =ROUND(C6*Premissas!$C$24/12,0) | M6: =ROUND(D6*Premissas!$C$25,0) | N6: =ROUND(E6*Premissas!$C$29+B6*Premissas!$C$30,0) | O6: =K6+L6+M6+N6 | P6: =K6+ROUND(AC6*Premissas!$C$24,0)+M6+N6 | Q6: =ROUND(IF(A6-1-Premissas!$C$21>=0,OFFSET($P$4,A6-1-Premissas!$C$21,0),0)*(1-Premissas!$C$20/100),0) | R6: =ROUND(F6*Premissas!$C$11+N6*Premissas!$C$31/100,0)+ROUND((E6+B6)*Premissas!$C$10,0)+ROUND(Q6*Premissas!$C$8/100,0)+ROUND(Premissas!$C$35+(B6+C6)*Premissas!$C$36,0) | S6: =O6-R6 | T6: =ROUND(O6*Premissas!$C$9/100,0) | U6: =ROUND(AB6*Premissas!$C$33,0) | V6: =Premissas!$C$37+ROUND(Premissas!$C$12*Premissas!$C$38+D6*Premissas!$C$27,0) | W6: =Premissas!$C$39 | X6: =S6-T6-ROUND(Premissas!$C$12*Premissas!$C$38+D6*Premissas!$C$27,0) | Y6: =O6-R6-T6-U6-V6-W6 | Z6: =Q6-R6-T6-U6-V6-W6 | AA6: =AA5+Z6 | AB6: =Premissas!$C$32+(B6+C6)/Premissas!$C$34 | AC6: =D6
A7: 4 | B7: =B6*(1-Premissas!$C$18/12)+Premissas!$C$12 | C7: =IF($B$2=1,C6*(1-Premissas!$C$26/12)+D7,0) | D7: =IF(AND($B$2=1,A7>=Premissas!$C$23),Premissas!$C$22,0) | E7: =B7*Premissas!$C$28 | F7: =B7*Premissas!$C$13/12*MIN(1,A7/Premissas!$C$17) | G7: =F7*Premissas!$C$14 | H7: =IF(IF(A7-1-Premissas!$C$16>=0,OFFSET($J$4,A7-1-Premissas!$C$16,0),0)>0,ROUND(IF(A7-1-Premissas!$C$16>=0,OFFSET($J$4,A7-1-Premissas!$C$16,0),0)*10000/Premissas!$C$5*Premissas!$C$15,0),0) | I7: =ROUND(G7*Premissas!$C$6/10000,0) | J7: =ROUND(G7*Premissas!$C$5/10000,0) | K7: =IF(IF(A7-1-Premissas!$C$16>=0,OFFSET($A$4,A7-1-Premissas!$C$16,0)>=Premissas!$C$19,FALSE),ROUND(IF(A7-1-Premissas!$C$16>=0,OFFSET($J$4,A7-1-Premissas!$C$16,0),0)*Premissas!$C$15,0),0) | L7: =ROUND(C7*Premissas!$C$24/12,0) | M7: =ROUND(D7*Premissas!$C$25,0) | N7: =ROUND(E7*Premissas!$C$29+B7*Premissas!$C$30,0) | O7: =K7+L7+M7+N7 | P7: =K7+ROUND(AC7*Premissas!$C$24,0)+M7+N7 | Q7: =ROUND(IF(A7-1-Premissas!$C$21>=0,OFFSET($P$4,A7-1-Premissas!$C$21,0),0)*(1-Premissas!$C$20/100),0) | R7: =ROUND(F7*Premissas!$C$11+N7*Premissas!$C$31/100,0)+ROUND((E7+B7)*Premissas!$C$10,0)+ROUND(Q7*Premissas!$C$8/100,0)+ROUND(Premissas!$C$35+(B7+C7)*Premissas!$C$36,0) | S7: =O7-R7 | T7: =ROUND(O7*Premissas!$C$9/100,0) | U7: =ROUND(AB7*Premissas!$C$33,0) | V7: =Premissas!$C$37+ROUND(Premissas!$C$12*Premissas!$C$38+D7*Premissas!$C$27,0) | W7: =Premissas!$C$39 | X7: =S7-T7-ROUND(Premissas!$C$12*Premissas!$C$38+D7*Premissas!$C$27,0) | Y7: =O7-R7-T7-U7-V7-W7 | Z7: =Q7-R7-T7-U7-V7-W7 | AA7: =AA6+Z7 | AB7: =Premissas!$C$32+(B7+C7)/Premissas!$C$34 | AC7: =D7
A8: 5 | B8: =B7*(1-Premissas!$C$18/12)+Premissas!$C$12 | C8: =IF($B$2=1,C7*(1-Premissas!$C$26/12)+D8,0) | D8: =IF(AND($B$2=1,A8>=Premissas!$C$23),Premissas!$C$22,0) | E8: =B8*Premissas!$C$28 | F8: =B8*Premissas!$C$13/12*MIN(1,A8/Premissas!$C$17) | G8: =F8*Premissas!$C$14 | H8: =IF(IF(A8-1-Premissas!$C$16>=0,OFFSET($J$4,A8-1-Premissas!$C$16,0),0)>0,ROUND(IF(A8-1-Premissas!$C$16>=0,OFFSET($J$4,A8-1-Premissas!$C$16,0),0)*10000/Premissas!$C$5*Premissas!$C$15,0),0) | I8: =ROUND(G8*Premissas!$C$6/10000,0) | J8: =ROUND(G8*Premissas!$C$5/10000,0) | K8: =IF(IF(A8-1-Premissas!$C$16>=0,OFFSET($A$4,A8-1-Premissas!$C$16,0)>=Premissas!$C$19,FALSE),ROUND(IF(A8-1-Premissas!$C$16>=0,OFFSET($J$4,A8-1-Premissas!$C$16,0),0)*Premissas!$C$15,0),0) | L8: =ROUND(C8*Premissas!$C$24/12,0) | M8: =ROUND(D8*Premissas!$C$25,0) | N8: =ROUND(E8*Premissas!$C$29+B8*Premissas!$C$30,0) | O8: =K8+L8+M8+N8 | P8: =K8+ROUND(AC8*Premissas!$C$24,0)+M8+N8 | Q8: =ROUND(IF(A8-1-Premissas!$C$21>=0,OFFSET($P$4,A8-1-Premissas!$C$21,0),0)*(1-Premissas!$C$20/100),0) | R8: =ROUND(F8*Premissas!$C$11+N8*Premissas!$C$31/100,0)+ROUND((E8+B8)*Premissas!$C$10,0)+ROUND(Q8*Premissas!$C$8/100,0)+ROUND(Premissas!$C$35+(B8+C8)*Premissas!$C$36,0) | S8: =O8-R8 | T8: =ROUND(O8*Premissas!$C$9/100,0) | U8: =ROUND(AB8*Premissas!$C$33,0) | V8: =Premissas!$C$37+ROUND(Premissas!$C$12*Premissas!$C$38+D8*Premissas!$C$27,0) | W8: =Premissas!$C$39 | X8: =S8-T8-ROUND(Premissas!$C$12*Premissas!$C$38+D8*Premissas!$C$27,0) | Y8: =O8-R8-T8-U8-V8-W8 | Z8: =Q8-R8-T8-U8-V8-W8 | AA8: =AA7+Z8 | AB8: =Premissas!$C$32+(B8+C8)/Premissas!$C$34 | AC8: =D8
A9: 6 | B9: =B8*(1-Premissas!$C$18/12)+Premissas!$C$12 | C9: =IF($B$2=1,C8*(1-Premissas!$C$26/12)+D9,0) | D9: =IF(AND($B$2=1,A9>=Premissas!$C$23),Premissas!$C$22,0) | E9: =B9*Premissas!$C$28 | F9: =B9*Premissas!$C$13/12*MIN(1,A9/Premissas!$C$17) | G9: =F9*Premissas!$C$14 | H9: =IF(IF(A9-1-Premissas!$C$16>=0,OFFSET($J$4,A9-1-Premissas!$C$16,0),0)>0,ROUND(IF(A9-1-Premissas!$C$16>=0,OFFSET($J$4,A9-1-Premissas!$C$16,0),0)*10000/Premissas!$C$5*Premissas!$C$15,0),0) | I9: =ROUND(G9*Premissas!$C$6/10000,0) | J9: =ROUND(G9*Premissas!$C$5/10000,0) | K9: =IF(IF(A9-1-Premissas!$C$16>=0,OFFSET($A$4,A9-1-Premissas!$C$16,0)>=Premissas!$C$19,FALSE),ROUND(IF(A9-1-Premissas!$C$16>=0,OFFSET($J$4,A9-1-Premissas!$C$16,0),0)*Premissas!$C$15,0),0) | L9: =ROUND(C9*Premissas!$C$24/12,0) | M9: =ROUND(D9*Premissas!$C$25,0) | N9: =ROUND(E9*Premissas!$C$29+B9*Premissas!$C$30,0) | O9: =K9+L9+M9+N9 | P9: =K9+ROUND(AC9*Premissas!$C$24,0)+M9+N9 | Q9: =ROUND(IF(A9-1-Premissas!$C$21>=0,OFFSET($P$4,A9-1-Premissas!$C$21,0),0)*(1-Premissas!$C$20/100),0) | R9: =ROUND(F9*Premissas!$C$11+N9*Premissas!$C$31/100,0)+ROUND((E9+B9)*Premissas!$C$10,0)+ROUND(Q9*Premissas!$C$8/100,0)+ROUND(Premissas!$C$35+(B9+C9)*Premissas!$C$36,0) | S9: =O9-R9 | T9: =ROUND(O9*Premissas!$C$9/100,0) | U9: =ROUND(AB9*Premissas!$C$33,0) | V9: =Premissas!$C$37+ROUND(Premissas!$C$12*Premissas!$C$38+D9*Premissas!$C$27,0) | W9: =Premissas!$C$39 | X9: =S9-T9-ROUND(Premissas!$C$12*Premissas!$C$38+D9*Premissas!$C$27,0) | Y9: =O9-R9-T9-U9-V9-W9 | Z9: =Q9-R9-T9-U9-V9-W9 | AA9: =AA8+Z9 | AB9: =Premissas!$C$32+(B9+C9)/Premissas!$C$34 | AC9: =D9
A10: 7 | B10: =B9*(1-Premissas!$C$18/12)+Premissas!$C$12 | C10: =IF($B$2=1,C9*(1-Premissas!$C$26/12)+D10,0) | D10: =IF(AND($B$2=1,A10>=Premissas!$C$23),Premissas!$C$22,0) | E10: =B10*Premissas!$C$28 | F10: =B10*Premissas!$C$13/12*MIN(1,A10/Premissas!$C$17) | G10: =F10*Premissas!$C$14 | H10: =IF(IF(A10-1-Premissas!$C$16>=0,OFFSET($J$4,A10-1-Premissas!$C$16,0),0)>0,ROUND(IF(A10-1-Premissas!$C$16>=0,OFFSET($J$4,A10-1-Premissas!$C$16,0),0)*10000/Premissas!$C$5*Premissas!$C$15,0),0) | I10: =ROUND(G10*Premissas!$C$6/10000,0) | J10: =ROUND(G10*Premissas!$C$5/10000,0) | K10: =IF(IF(A10-1-Premissas!$C$16>=0,OFFSET($A$4,A10-1-Premissas!$C$16,0)>=Premissas!$C$19,FALSE),ROUND(IF(A10-1-Premissas!$C$16>=0,OFFSET($J$4,A10-1-Premissas!$C$16,0),0)*Premissas!$C$15,0),0) | L10: =ROUND(C10*Premissas!$C$24/12,0) | M10: =ROUND(D10*Premissas!$C$25,0) | N10: =ROUND(E10*Premissas!$C$29+B10*Premissas!$C$30,0) | O10: =K10+L10+M10+N10 | P10: =K10+ROUND(AC10*Premissas!$C$24,0)+M10+N10 | Q10: =ROUND(IF(A10-1-Premissas!$C$21>=0,OFFSET($P$4,A10-1-Premissas!$C$21,0),0)*(1-Premissas!$C$20/100),0) | R10: =ROUND(F10*Premissas!$C$11+N10*Premissas!$C$31/100,0)+ROUND((E10+B10)*Premissas!$C$10,0)+ROUND(Q10*Premissas!$C$8/100,0)+ROUND(Premissas!$C$35+(B10+C10)*Premissas!$C$36,0) | S10: =O10-R10 | T10: =ROUND(O10*Premissas!$C$9/100,0) | U10: =ROUND(AB10*Premissas!$C$33,0) | V10: =Premissas!$C$37+ROUND(Premissas!$C$12*Premissas!$C$38+D10*Premissas!$C$27,0) | W10: =Premissas!$C$39 | X10: =S10-T10-ROUND(Premissas!$C$12*Premissas!$C$38+D10*Premissas!$C$27,0) | Y10: =O10-R10-T10-U10-V10-W10 | Z10: =Q10-R10-T10-U10-V10-W10 | AA10: =AA9+Z10 | AB10: =Premissas!$C$32+(B10+C10)/Premissas!$C$34 | AC10: =D10
A11: 8 | B11: =B10*(1-Premissas!$C$18/12)+Premissas!$C$12 | C11: =IF($B$2=1,C10*(1-Premissas!$C$26/12)+D11,0) | D11: =IF(AND($B$2=1,A11>=Premissas!$C$23),Premissas!$C$22,0) | E11: =B11*Premissas!$C$28 | F11: =B11*Premissas!$C$13/12*MIN(1,A11/Premissas!$C$17) | G11: =F11*Premissas!$C$14 | H11: =IF(IF(A11-1-Premissas!$C$16>=0,OFFSET($J$4,A11-1-Premissas!$C$16,0),0)>0,ROUND(IF(A11-1-Premissas!$C$16>=0,OFFSET($J$4,A11-1-Premissas!$C$16,0),0)*10000/Premissas!$C$5*Premissas!$C$15,0),0) | I11: =ROUND(G11*Premissas!$C$6/10000,0) | J11: =ROUND(G11*Premissas!$C$5/10000,0) | K11: =IF(IF(A11-1-Premissas!$C$16>=0,OFFSET($A$4,A11-1-Premissas!$C$16,0)>=Premissas!$C$19,FALSE),ROUND(IF(A11-1-Premissas!$C$16>=0,OFFSET($J$4,A11-1-Premissas!$C$16,0),0)*Premissas!$C$15,0),0) | L11: =ROUND(C11*Premissas!$C$24/12,0) | M11: =ROUND(D11*Premissas!$C$25,0) | N11: =ROUND(E11*Premissas!$C$29+B11*Premissas!$C$30,0) | O11: =K11+L11+M11+N11 | P11: =K11+ROUND(AC11*Premissas!$C$24,0)+M11+N11 | Q11: =ROUND(IF(A11-1-Premissas!$C$21>=0,OFFSET($P$4,A11-1-Premissas!$C$21,0),0)*(1-Premissas!$C$20/100),0) | R11: =ROUND(F11*Premissas!$C$11+N11*Premissas!$C$31/100,0)+ROUND((E11+B11)*Premissas!$C$10,0)+ROUND(Q11*Premissas!$C$8/100,0)+ROUND(Premissas!$C$35+(B11+C11)*Premissas!$C$36,0) | S11: =O11-R11 | T11: =ROUND(O11*Premissas!$C$9/100,0) | U11: =ROUND(AB11*Premissas!$C$33,0) | V11: =Premissas!$C$37+ROUND(Premissas!$C$12*Premissas!$C$38+D11*Premissas!$C$27,0) | W11: =Premissas!$C$39 | X11: =S11-T11-ROUND(Premissas!$C$12*Premissas!$C$38+D11*Premissas!$C$27,0) | Y11: =O11-R11-T11-U11-V11-W11 | Z11: =Q11-R11-T11-U11-V11-W11 | AA11: =AA10+Z11 | AB11: =Premissas!$C$32+(B11+C11)/Premissas!$C$34 | AC11: =D11
A12: 9 | B12: =B11*(1-Premissas!$C$18/12)+Premissas!$C$12 | C12: =IF($B$2=1,C11*(1-Premissas!$C$26/12)+D12,0) | D12: =IF(AND($B$2=1,A12>=Premissas!$C$23),Premissas!$C$22,0) | E12: =B12*Premissas!$C$28 | F12: =B12*Premissas!$C$13/12*MIN(1,A12/Premissas!$C$17) | G12: =F12*Premissas!$C$14 | H12: =IF(IF(A12-1-Premissas!$C$16>=0,OFFSET($J$4,A12-1-Premissas!$C$16,0),0)>0,ROUND(IF(A12-1-Premissas!$C$16>=0,OFFSET($J$4,A12-1-Premissas!$C$16,0),0)*10000/Premissas!$C$5*Premissas!$C$15,0),0) | I12: =ROUND(G12*Premissas!$C$6/10000,0) | J12: =ROUND(G12*Premissas!$C$5/10000,0) | K12: =IF(IF(A12-1-Premissas!$C$16>=0,OFFSET($A$4,A12-1-Premissas!$C$16,0)>=Premissas!$C$19,FALSE),ROUND(IF(A12-1-Premissas!$C$16>=0,OFFSET($J$4,A12-1-Premissas!$C$16,0),0)*Premissas!$C$15,0),0) | L12: =ROUND(C12*Premissas!$C$24/12,0) | M12: =ROUND(D12*Premissas!$C$25,0) | N12: =ROUND(E12*Premissas!$C$29+B12*Premissas!$C$30,0) | O12: =K12+L12+M12+N12 | P12: =K12+ROUND(AC12*Premissas!$C$24,0)+M12+N12 | Q12: =ROUND(IF(A12-1-Premissas!$C$21>=0,OFFSET($P$4,A12-1-Premissas!$C$21,0),0)*(1-Premissas!$C$20/100),0) | R12: =ROUND(F12*Premissas!$C$11+N12*Premissas!$C$31/100,0)+ROUND((E12+B12)*Premissas!$C$10,0)+ROUND(Q12*Premissas!$C$8/100,0)+ROUND(Premissas!$C$35+(B12+C12)*Premissas!$C$36,0) | S12: =O12-R12 | T12: =ROUND(O12*Premissas!$C$9/100,0) | U12: =ROUND(AB12*Premissas!$C$33,0) | V12: =Premissas!$C$37+ROUND(Premissas!$C$12*Premissas!$C$38+D12*Premissas!$C$27,0) | W12: =Premissas!$C$39 | X12: =S12-T12-ROUND(Premissas!$C$12*Premissas!$C$38+D12*Premissas!$C$27,0) | Y12: =O12-R12-T12-U12-V12-W12 | Z12: =Q12-R12-T12-U12-V12-W12 | AA12: =AA11+Z12 | AB12: =Premissas!$C$32+(B12+C12)/Premissas!$C$34 | AC12: =D12
A13: 10 | B13: =B12*(1-Premissas!$C$18/12)+Premissas!$C$12 | C13: =IF($B$2=1,C12*(1-Premissas!$C$26/12)+D13,0) | D13: =IF(AND($B$2=1,A13>=Premissas!$C$23),Premissas!$C$22,0) | E13: =B13*Premissas!$C$28 | F13: =B13*Premissas!$C$13/12*MIN(1,A13/Premissas!$C$17) | G13: =F13*Premissas!$C$14 | H13: =IF(IF(A13-1-Premissas!$C$16>=0,OFFSET($J$4,A13-1-Premissas!$C$16,0),0)>0,ROUND(IF(A13-1-Premissas!$C$16>=0,OFFSET($J$4,A13-1-Premissas!$C$16,0),0)*10000/Premissas!$C$5*Premissas!$C$15,0),0) | I13: =ROUND(G13*Premissas!$C$6/10000,0) | J13: =ROUND(G13*Premissas!$C$5/10000,0) | K13: =IF(IF(A13-1-Premissas!$C$16>=0,OFFSET($A$4,A13-1-Premissas!$C$16,0)>=Premissas!$C$19,FALSE),ROUND(IF(A13-1-Premissas!$C$16>=0,OFFSET($J$4,A13-1-Premissas!$C$16,0),0)*Premissas!$C$15,0),0) | L13: =ROUND(C13*Premissas!$C$24/12,0) | M13: =ROUND(D13*Premissas!$C$25,0) | N13: =ROUND(E13*Premissas!$C$29+B13*Premissas!$C$30,0) | O13: =K13+L13+M13+N13 | P13: =K13+ROUND(AC13*Premissas!$C$24,0)+M13+N13 | Q13: =ROUND(IF(A13-1-Premissas!$C$21>=0,OFFSET($P$4,A13-1-Premissas!$C$21,0),0)*(1-Premissas!$C$20/100),0) | R13: =ROUND(F13*Premissas!$C$11+N13*Premissas!$C$31/100,0)+ROUND((E13+B13)*Premissas!$C$10,0)+ROUND(Q13*Premissas!$C$8/100,0)+ROUND(Premissas!$C$35+(B13+C13)*Premissas!$C$36,0) | S13: =O13-R13 | T13: =ROUND(O13*Premissas!$C$9/100,0) | U13: =ROUND(AB13*Premissas!$C$33,0) | V13: =Premissas!$C$37+ROUND(Premissas!$C$12*Premissas!$C$38+D13*Premissas!$C$27,0) | W13: =Premissas!$C$39 | X13: =S13-T13-ROUND(Premissas!$C$12*Premissas!$C$38+D13*Premissas!$C$27,0) | Y13: =O13-R13-T13-U13-V13-W13 | Z13: =Q13-R13-T13-U13-V13-W13 | AA13: =AA12+Z13 | AB13: =Premissas!$C$32+(B13+C13)/Premissas!$C$34 | AC13: =D13
A14: 11 | B14: =B13*(1-Premissas!$C$18/12)+Premissas!$C$12 | C14: =IF($B$2=1,C13*(1-Premissas!$C$26/12)+D14,0) | D14: =IF(AND($B$2=1,A14>=Premissas!$C$23),Premissas!$C$22,0) | E14: =B14*Premissas!$C$28 | F14: =B14*Premissas!$C$13/12*MIN(1,A14/Premissas!$C$17) | G14: =F14*Premissas!$C$14 | H14: =IF(IF(A14-1-Premissas!$C$16>=0,OFFSET($J$4,A14-1-Premissas!$C$16,0),0)>0,ROUND(IF(A14-1-Premissas!$C$16>=0,OFFSET($J$4,A14-1-Premissas!$C$16,0),0)*10000/Premissas!$C$5*Premissas!$C$15,0),0) | I14: =ROUND(G14*Premissas!$C$6/10000,0) | J14: =ROUND(G14*Premissas!$C$5/10000,0) | K14: =IF(IF(A14-1-Premissas!$C$16>=0,OFFSET($A$4,A14-1-Premissas!$C$16,0)>=Premissas!$C$19,FALSE),ROUND(IF(A14-1-Premissas!$C$16>=0,OFFSET($J$4,A14-1-Premissas!$C$16,0),0)*Premissas!$C$15,0),0) | L14: =ROUND(C14*Premissas!$C$24/12,0) | M14: =ROUND(D14*Premissas!$C$25,0) | N14: =ROUND(E14*Premissas!$C$29+B14*Premissas!$C$30,0) | O14: =K14+L14+M14+N14 | P14: =K14+ROUND(AC14*Premissas!$C$24,0)+M14+N14 | Q14: =ROUND(IF(A14-1-Premissas!$C$21>=0,OFFSET($P$4,A14-1-Premissas!$C$21,0),0)*(1-Premissas!$C$20/100),0) | R14: =ROUND(F14*Premissas!$C$11+N14*Premissas!$C$31/100,0)+ROUND((E14+B14)*Premissas!$C$10,0)+ROUND(Q14*Premissas!$C$8/100,0)+ROUND(Premissas!$C$35+(B14+C14)*Premissas!$C$36,0) | S14: =O14-R14 | T14: =ROUND(O14*Premissas!$C$9/100,0) | U14: =ROUND(AB14*Premissas!$C$33,0) | V14: =Premissas!$C$37+ROUND(Premissas!$C$12*Premissas!$C$38+D14*Premissas!$C$27,0) | W14: =Premissas!$C$39 | X14: =S14-T14-ROUND(Premissas!$C$12*Premissas!$C$38+D14*Premissas!$C$27,0) | Y14: =O14-R14-T14-U14-V14-W14 | Z14: =Q14-R14-T14-U14-V14-W14 | AA14: =AA13+Z14 | AB14: =Premissas!$C$32+(B14+C14)/Premissas!$C$34 | AC14: =D14
A15: 12 | B15: =B14*(1-Premissas!$C$18/12)+Premissas!$C$12 | C15: =IF($B$2=1,C14*(1-Premissas!$C$26/12)+D15,0) | D15: =IF(AND($B$2=1,A15>=Premissas!$C$23),Premissas!$C$22,0) | E15: =B15*Premissas!$C$28 | F15: =B15*Premissas!$C$13/12*MIN(1,A15/Premissas!$C$17) | G15: =F15*Premissas!$C$14 | H15: =IF(IF(A15-1-Premissas!$C$16>=0,OFFSET($J$4,A15-1-Premissas!$C$16,0),0)>0,ROUND(IF(A15-1-Premissas!$C$16>=0,OFFSET($J$4,A15-1-Premissas!$C$16,0),0)*10000/Premissas!$C$5*Premissas!$C$15,0),0) | I15: =ROUND(G15*Premissas!$C$6/10000,0) | J15: =ROUND(G15*Premissas!$C$5/10000,0) | K15: =IF(IF(A15-1-Premissas!$C$16>=0,OFFSET($A$4,A15-1-Premissas!$C$16,0)>=Premissas!$C$19,FALSE),ROUND(IF(A15-1-Premissas!$C$16>=0,OFFSET($J$4,A15-1-Premissas!$C$16,0),0)*Premissas!$C$15,0),0) | L15: =ROUND(C15*Premissas!$C$24/12,0) | M15: =ROUND(D15*Premissas!$C$25,0) | N15: =ROUND(E15*Premissas!$C$29+B15*Premissas!$C$30,0) | O15: =K15+L15+M15+N15 | P15: =K15+ROUND(AC15*Premissas!$C$24,0)+M15+N15 | Q15: =ROUND(IF(A15-1-Premissas!$C$21>=0,OFFSET($P$4,A15-1-Premissas!$C$21,0),0)*(1-Premissas!$C$20/100),0) | R15: =ROUND(F15*Premissas!$C$11+N15*Premissas!$C$31/100,0)+ROUND((E15+B15)*Premissas!$C$10,0)+ROUND(Q15*Premissas!$C$8/100,0)+ROUND(Premissas!$C$35+(B15+C15)*Premissas!$C$36,0) | S15: =O15-R15 | T15: =ROUND(O15*Premissas!$C$9/100,0) | U15: =ROUND(AB15*Premissas!$C$33,0) | V15: =Premissas!$C$37+ROUND(Premissas!$C$12*Premissas!$C$38+D15*Premissas!$C$27,0) | W15: =Premissas!$C$39 | X15: =S15-T15-ROUND(Premissas!$C$12*Premissas!$C$38+D15*Premissas!$C$27,0) | Y15: =O15-R15-T15-U15-V15-W15 | Z15: =Q15-R15-T15-U15-V15-W15 | AA15: =AA14+Z15 | AB15: =Premissas!$C$32+(B15+C15)/Premissas!$C$34 | AC15: =D15
A16: 13 | B16: =B15*(1-Premissas!$C$18/12)+Premissas!$C$12 | C16: =IF($B$2=1,C15*(1-Premissas!$C$26/12)+D16,0) | D16: =IF(AND($B$2=1,A16>=Premissas!$C$23),Premissas!$C$22,0) | E16: =B16*Premissas!$C$28 | F16: =B16*Premissas!$C$13/12*MIN(1,A16/Premissas!$C$17) | G16: =F16*Premissas!$C$14 | H16: =IF(IF(A16-1-Premissas!$C$16>=0,OFFSET($J$4,A16-1-Premissas!$C$16,0),0)>0,ROUND(IF(A16-1-Premissas!$C$16>=0,OFFSET($J$4,A16-1-Premissas!$C$16,0),0)*10000/Premissas!$C$5*Premissas!$C$15,0),0) | I16: =ROUND(G16*Premissas!$C$6/10000,0) | J16: =ROUND(G16*Premissas!$C$5/10000,0) | K16: =IF(IF(A16-1-Premissas!$C$16>=0,OFFSET($A$4,A16-1-Premissas!$C$16,0)>=Premissas!$C$19,FALSE),ROUND(IF(A16-1-Premissas!$C$16>=0,OFFSET($J$4,A16-1-Premissas!$C$16,0),0)*Premissas!$C$15,0),0) | L16: =ROUND(C16*Premissas!$C$24/12,0) | M16: =ROUND(D16*Premissas!$C$25,0) | N16: =ROUND(E16*Premissas!$C$29+B16*Premissas!$C$30,0) | O16: =K16+L16+M16+N16 | P16: =K16+ROUND(AC16*Premissas!$C$24,0)+M16+N16 | Q16: =ROUND(IF(A16-1-Premissas!$C$21>=0,OFFSET($P$4,A16-1-Premissas!$C$21,0),0)*(1-Premissas!$C$20/100),0) | R16: =ROUND(F16*Premissas!$C$11+N16*Premissas!$C$31/100,0)+ROUND((E16+B16)*Premissas!$C$10,0)+ROUND(Q16*Premissas!$C$8/100,0)+ROUND(Premissas!$C$35+(B16+C16)*Premissas!$C$36,0) | S16: =O16-R16 | T16: =ROUND(O16*Premissas!$C$9/100,0) | U16: =ROUND(AB16*Premissas!$C$33,0) | V16: =Premissas!$C$37+ROUND(Premissas!$C$12*Premissas!$C$38+D16*Premissas!$C$27,0) | W16: =Premissas!$C$39 | X16: =S16-T16-ROUND(Premissas!$C$12*Premissas!$C$38+D16*Premissas!$C$27,0) | Y16: =O16-R16-T16-U16-V16-W16 | Z16: =Q16-R16-T16-U16-V16-W16 | AA16: =AA15+Z16 | AB16: =Premissas!$C$32+(B16+C16)/Premissas!$C$34 | AC16: =D16+AC4*(1-Premissas!$C$26/12)^12
A17: 14 | B17: =B16*(1-Premissas!$C$18/12)+Premissas!$C$12 | C17: =IF($B$2=1,C16*(1-Premissas!$C$26/12)+D17,0) | D17: =IF(AND($B$2=1,A17>=Premissas!$C$23),Premissas!$C$22,0) | E17: =B17*Premissas!$C$28 | F17: =B17*Premissas!$C$13/12*MIN(1,A17/Premissas!$C$17) | G17: =F17*Premissas!$C$14 | H17: =IF(IF(A17-1-Premissas!$C$16>=0,OFFSET($J$4,A17-1-Premissas!$C$16,0),0)>0,ROUND(IF(A17-1-Premissas!$C$16>=0,OFFSET($J$4,A17-1-Premissas!$C$16,0),0)*10000/Premissas!$C$5*Premissas!$C$15,0),0) | I17: =ROUND(G17*Premissas!$C$6/10000,0) | J17: =ROUND(G17*Premissas!$C$5/10000,0) | K17: =IF(IF(A17-1-Premissas!$C$16>=0,OFFSET($A$4,A17-1-Premissas!$C$16,0)>=Premissas!$C$19,FALSE),ROUND(IF(A17-1-Premissas!$C$16>=0,OFFSET($J$4,A17-1-Premissas!$C$16,0),0)*Premissas!$C$15,0),0) | L17: =ROUND(C17*Premissas!$C$24/12,0) | M17: =ROUND(D17*Premissas!$C$25,0) | N17: =ROUND(E17*Premissas!$C$29+B17*Premissas!$C$30,0) | O17: =K17+L17+M17+N17 | P17: =K17+ROUND(AC17*Premissas!$C$24,0)+M17+N17 | Q17: =ROUND(IF(A17-1-Premissas!$C$21>=0,OFFSET($P$4,A17-1-Premissas!$C$21,0),0)*(1-Premissas!$C$20/100),0) | R17: =ROUND(F17*Premissas!$C$11+N17*Premissas!$C$31/100,0)+ROUND((E17+B17)*Premissas!$C$10,0)+ROUND(Q17*Premissas!$C$8/100,0)+ROUND(Premissas!$C$35+(B17+C17)*Premissas!$C$36,0) | S17: =O17-R17 | T17: =ROUND(O17*Premissas!$C$9/100,0) | U17: =ROUND(AB17*Premissas!$C$33,0) | V17: =Premissas!$C$37+ROUND(Premissas!$C$12*Premissas!$C$38+D17*Premissas!$C$27,0) | W17: =Premissas!$C$39 | X17: =S17-T17-ROUND(Premissas!$C$12*Premissas!$C$38+D17*Premissas!$C$27,0) | Y17: =O17-R17-T17-U17-V17-W17 | Z17: =Q17-R17-T17-U17-V17-W17 | AA17: =AA16+Z17 | AB17: =Premissas!$C$32+(B17+C17)/Premissas!$C$34 | AC17: =D17+AC5*(1-Premissas!$C$26/12)^12
A18: 15 | B18: =B17*(1-Premissas!$C$18/12)+Premissas!$C$12 | C18: =IF($B$2=1,C17*(1-Premissas!$C$26/12)+D18,0) | D18: =IF(AND($B$2=1,A18>=Premissas!$C$23),Premissas!$C$22,0) | E18: =B18*Premissas!$C$28 | F18: =B18*Premissas!$C$13/12*MIN(1,A18/Premissas!$C$17) | G18: =F18*Premissas!$C$14 | H18: =IF(IF(A18-1-Premissas!$C$16>=0,OFFSET($J$4,A18-1-Premissas!$C$16,0),0)>0,ROUND(IF(A18-1-Premissas!$C$16>=0,OFFSET($J$4,A18-1-Premissas!$C$16,0),0)*10000/Premissas!$C$5*Premissas!$C$15,0),0) | I18: =ROUND(G18*Premissas!$C$6/10000,0) | J18: =ROUND(G18*Premissas!$C$5/10000,0) | K18: =IF(IF(A18-1-Premissas!$C$16>=0,OFFSET($A$4,A18-1-Premissas!$C$16,0)>=Premissas!$C$19,FALSE),ROUND(IF(A18-1-Premissas!$C$16>=0,OFFSET($J$4,A18-1-Premissas!$C$16,0),0)*Premissas!$C$15,0),0) | L18: =ROUND(C18*Premissas!$C$24/12,0) | M18: =ROUND(D18*Premissas!$C$25,0) | N18: =ROUND(E18*Premissas!$C$29+B18*Premissas!$C$30,0) | O18: =K18+L18+M18+N18 | P18: =K18+ROUND(AC18*Premissas!$C$24,0)+M18+N18 | Q18: =ROUND(IF(A18-1-Premissas!$C$21>=0,OFFSET($P$4,A18-1-Premissas!$C$21,0),0)*(1-Premissas!$C$20/100),0) | R18: =ROUND(F18*Premissas!$C$11+N18*Premissas!$C$31/100,0)+ROUND((E18+B18)*Premissas!$C$10,0)+ROUND(Q18*Premissas!$C$8/100,0)+ROUND(Premissas!$C$35+(B18+C18)*Premissas!$C$36,0) | S18: =O18-R18 | T18: =ROUND(O18*Premissas!$C$9/100,0) | U18: =ROUND(AB18*Premissas!$C$33,0) | V18: =Premissas!$C$37+ROUND(Premissas!$C$12*Premissas!$C$38+D18*Premissas!$C$27,0) | W18: =Premissas!$C$39 | X18: =S18-T18-ROUND(Premissas!$C$12*Premissas!$C$38+D18*Premissas!$C$27,0) | Y18: =O18-R18-T18-U18-V18-W18 | Z18: =Q18-R18-T18-U18-V18-W18 | AA18: =AA17+Z18 | AB18: =Premissas!$C$32+(B18+C18)/Premissas!$C$34 | AC18: =D18+AC6*(1-Premissas!$C$26/12)^12
A19: 16 | B19: =B18*(1-Premissas!$C$18/12)+Premissas!$C$12 | C19: =IF($B$2=1,C18*(1-Premissas!$C$26/12)+D19,0) | D19: =IF(AND($B$2=1,A19>=Premissas!$C$23),Premissas!$C$22,0) | E19: =B19*Premissas!$C$28 | F19: =B19*Premissas!$C$13/12*MIN(1,A19/Premissas!$C$17) | G19: =F19*Premissas!$C$14 | H19: =IF(IF(A19-1-Premissas!$C$16>=0,OFFSET($J$4,A19-1-Premissas!$C$16,0),0)>0,ROUND(IF(A19-1-Premissas!$C$16>=0,OFFSET($J$4,A19-1-Premissas!$C$16,0),0)*10000/Premissas!$C$5*Premissas!$C$15,0),0) | I19: =ROUND(G19*Premissas!$C$6/10000,0) | J19: =ROUND(G19*Premissas!$C$5/10000,0) | K19: =IF(IF(A19-1-Premissas!$C$16>=0,OFFSET($A$4,A19-1-Premissas!$C$16,0)>=Premissas!$C$19,FALSE),ROUND(IF(A19-1-Premissas!$C$16>=0,OFFSET($J$4,A19-1-Premissas!$C$16,0),0)*Premissas!$C$15,0),0) | L19: =ROUND(C19*Premissas!$C$24/12,0) | M19: =ROUND(D19*Premissas!$C$25,0) | N19: =ROUND(E19*Premissas!$C$29+B19*Premissas!$C$30,0) | O19: =K19+L19+M19+N19 | P19: =K19+ROUND(AC19*Premissas!$C$24,0)+M19+N19 | Q19: =ROUND(IF(A19-1-Premissas!$C$21>=0,OFFSET($P$4,A19-1-Premissas!$C$21,0),0)*(1-Premissas!$C$20/100),0) | R19: =ROUND(F19*Premissas!$C$11+N19*Premissas!$C$31/100,0)+ROUND((E19+B19)*Premissas!$C$10,0)+ROUND(Q19*Premissas!$C$8/100,0)+ROUND(Premissas!$C$35+(B19+C19)*Premissas!$C$36,0) | S19: =O19-R19 | T19: =ROUND(O19*Premissas!$C$9/100,0) | U19: =ROUND(AB19*Premissas!$C$33,0) | V19: =Premissas!$C$37+ROUND(Premissas!$C$12*Premissas!$C$38+D19*Premissas!$C$27,0) | W19: =Premissas!$C$39 | X19: =S19-T19-ROUND(Premissas!$C$12*Premissas!$C$38+D19*Premissas!$C$27,0) | Y19: =O19-R19-T19-U19-V19-W19 | Z19: =Q19-R19-T19-U19-V19-W19 | AA19: =AA18+Z19 | AB19: =Premissas!$C$32+(B19+C19)/Premissas!$C$34 | AC19: =D19+AC7*(1-Premissas!$C$26/12)^12
A20: 17 | B20: =B19*(1-Premissas!$C$18/12)+Premissas!$C$12 | C20: =IF($B$2=1,C19*(1-Premissas!$C$26/12)+D20,0) | D20: =IF(AND($B$2=1,A20>=Premissas!$C$23),Premissas!$C$22,0) | E20: =B20*Premissas!$C$28 | F20: =B20*Premissas!$C$13/12*MIN(1,A20/Premissas!$C$17) | G20: =F20*Premissas!$C$14 | H20: =IF(IF(A20-1-Premissas!$C$16>=0,OFFSET($J$4,A20-1-Premissas!$C$16,0),0)>0,ROUND(IF(A20-1-Premissas!$C$16>=0,OFFSET($J$4,A20-1-Premissas!$C$16,0),0)*10000/Premissas!$C$5*Premissas!$C$15,0),0) | I20: =ROUND(G20*Premissas!$C$6/10000,0) | J20: =ROUND(G20*Premissas!$C$5/10000,0) | K20: =IF(IF(A20-1-Premissas!$C$16>=0,OFFSET($A$4,A20-1-Premissas!$C$16,0)>=Premissas!$C$19,FALSE),ROUND(IF(A20-1-Premissas!$C$16>=0,OFFSET($J$4,A20-1-Premissas!$C$16,0),0)*Premissas!$C$15,0),0) | L20: =ROUND(C20*Premissas!$C$24/12,0) | M20: =ROUND(D20*Premissas!$C$25,0) | N20: =ROUND(E20*Premissas!$C$29+B20*Premissas!$C$30,0) | O20: =K20+L20+M20+N20 | P20: =K20+ROUND(AC20*Premissas!$C$24,0)+M20+N20 | Q20: =ROUND(IF(A20-1-Premissas!$C$21>=0,OFFSET($P$4,A20-1-Premissas!$C$21,0),0)*(1-Premissas!$C$20/100),0) | R20: =ROUND(F20*Premissas!$C$11+N20*Premissas!$C$31/100,0)+ROUND((E20+B20)*Premissas!$C$10,0)+ROUND(Q20*Premissas!$C$8/100,0)+ROUND(Premissas!$C$35+(B20+C20)*Premissas!$C$36,0) | S20: =O20-R20 | T20: =ROUND(O20*Premissas!$C$9/100,0) | U20: =ROUND(AB20*Premissas!$C$33,0) | V20: =Premissas!$C$37+ROUND(Premissas!$C$12*Premissas!$C$38+D20*Premissas!$C$27,0) | W20: =Premissas!$C$39 | X20: =S20-T20-ROUND(Premissas!$C$12*Premissas!$C$38+D20*Premissas!$C$27,0) | Y20: =O20-R20-T20-U20-V20-W20 | Z20: =Q20-R20-T20-U20-V20-W20 | AA20: =AA19+Z20 | AB20: =Premissas!$C$32+(B20+C20)/Premissas!$C$34 | AC20: =D20+AC8*(1-Premissas!$C$26/12)^12
A21: 18 | B21: =B20*(1-Premissas!$C$18/12)+Premissas!$C$12 | C21: =IF($B$2=1,C20*(1-Premissas!$C$26/12)+D21,0) | D21: =IF(AND($B$2=1,A21>=Premissas!$C$23),Premissas!$C$22,0) | E21: =B21*Premissas!$C$28 | F21: =B21*Premissas!$C$13/12*MIN(1,A21/Premissas!$C$17) | G21: =F21*Premissas!$C$14 | H21: =IF(IF(A21-1-Premissas!$C$16>=0,OFFSET($J$4,A21-1-Premissas!$C$16,0),0)>0,ROUND(IF(A21-1-Premissas!$C$16>=0,OFFSET($J$4,A21-1-Premissas!$C$16,0),0)*10000/Premissas!$C$5*Premissas!$C$15,0),0) | I21: =ROUND(G21*Premissas!$C$6/10000,0) | J21: =ROUND(G21*Premissas!$C$5/10000,0) | K21: =IF(IF(A21-1-Premissas!$C$16>=0,OFFSET($A$4,A21-1-Premissas!$C$16,0)>=Premissas!$C$19,FALSE),ROUND(IF(A21-1-Premissas!$C$16>=0,OFFSET($J$4,A21-1-Premissas!$C$16,0),0)*Premissas!$C$15,0),0) | L21: =ROUND(C21*Premissas!$C$24/12,0) | M21: =ROUND(D21*Premissas!$C$25,0) | N21: =ROUND(E21*Premissas!$C$29+B21*Premissas!$C$30,0) | O21: =K21+L21+M21+N21 | P21: =K21+ROUND(AC21*Premissas!$C$24,0)+M21+N21 | Q21: =ROUND(IF(A21-1-Premissas!$C$21>=0,OFFSET($P$4,A21-1-Premissas!$C$21,0),0)*(1-Premissas!$C$20/100),0) | R21: =ROUND(F21*Premissas!$C$11+N21*Premissas!$C$31/100,0)+ROUND((E21+B21)*Premissas!$C$10,0)+ROUND(Q21*Premissas!$C$8/100,0)+ROUND(Premissas!$C$35+(B21+C21)*Premissas!$C$36,0) | S21: =O21-R21 | T21: =ROUND(O21*Premissas!$C$9/100,0) | U21: =ROUND(AB21*Premissas!$C$33,0) | V21: =Premissas!$C$37+ROUND(Premissas!$C$12*Premissas!$C$38+D21*Premissas!$C$27,0) | W21: =Premissas!$C$39 | X21: =S21-T21-ROUND(Premissas!$C$12*Premissas!$C$38+D21*Premissas!$C$27,0) | Y21: =O21-R21-T21-U21-V21-W21 | Z21: =Q21-R21-T21-U21-V21-W21 | AA21: =AA20+Z21 | AB21: =Premissas!$C$32+(B21+C21)/Premissas!$C$34 | AC21: =D21+AC9*(1-Premissas!$C$26/12)^12
A22: 19 | B22: =B21*(1-Premissas!$C$18/12)+Premissas!$C$12 | C22: =IF($B$2=1,C21*(1-Premissas!$C$26/12)+D22,0) | D22: =IF(AND($B$2=1,A22>=Premissas!$C$23),Premissas!$C$22,0) | E22: =B22*Premissas!$C$28 | F22: =B22*Premissas!$C$13/12*MIN(1,A22/Premissas!$C$17) | G22: =F22*Premissas!$C$14 | H22: =IF(IF(A22-1-Premissas!$C$16>=0,OFFSET($J$4,A22-1-Premissas!$C$16,0),0)>0,ROUND(IF(A22-1-Premissas!$C$16>=0,OFFSET($J$4,A22-1-Premissas!$C$16,0),0)*10000/Premissas!$C$5*Premissas!$C$15,0),0) | I22: =ROUND(G22*Premissas!$C$6/10000,0) | J22: =ROUND(G22*Premissas!$C$5/10000,0) | K22: =IF(IF(A22-1-Premissas!$C$16>=0,OFFSET($A$4,A22-1-Premissas!$C$16,0)>=Premissas!$C$19,FALSE),ROUND(IF(A22-1-Premissas!$C$16>=0,OFFSET($J$4,A22-1-Premissas!$C$16,0),0)*Premissas!$C$15,0),0) | L22: =ROUND(C22*Premissas!$C$24/12,0) | M22: =ROUND(D22*Premissas!$C$25,0) | N22: =ROUND(E22*Premissas!$C$29+B22*Premissas!$C$30,0) | O22: =K22+L22+M22+N22 | P22: =K22+ROUND(AC22*Premissas!$C$24,0)+M22+N22 | Q22: =ROUND(IF(A22-1-Premissas!$C$21>=0,OFFSET($P$4,A22-1-Premissas!$C$21,0),0)*(1-Premissas!$C$20/100),0) | R22: =ROUND(F22*Premissas!$C$11+N22*Premissas!$C$31/100,0)+ROUND((E22+B22)*Premissas!$C$10,0)+ROUND(Q22*Premissas!$C$8/100,0)+ROUND(Premissas!$C$35+(B22+C22)*Premissas!$C$36,0) | S22: =O22-R22 | T22: =ROUND(O22*Premissas!$C$9/100,0) | U22: =ROUND(AB22*Premissas!$C$33,0) | V22: =Premissas!$C$37+ROUND(Premissas!$C$12*Premissas!$C$38+D22*Premissas!$C$27,0) | W22: =Premissas!$C$39 | X22: =S22-T22-ROUND(Premissas!$C$12*Premissas!$C$38+D22*Premissas!$C$27,0) | Y22: =O22-R22-T22-U22-V22-W22 | Z22: =Q22-R22-T22-U22-V22-W22 | AA22: =AA21+Z22 | AB22: =Premissas!$C$32+(B22+C22)/Premissas!$C$34 | AC22: =D22+AC10*(1-Premissas!$C$26/12)^12
A23: 20 | B23: =B22*(1-Premissas!$C$18/12)+Premissas!$C$12 | C23: =IF($B$2=1,C22*(1-Premissas!$C$26/12)+D23,0) | D23: =IF(AND($B$2=1,A23>=Premissas!$C$23),Premissas!$C$22,0) | E23: =B23*Premissas!$C$28 | F23: =B23*Premissas!$C$13/12*MIN(1,A23/Premissas!$C$17) | G23: =F23*Premissas!$C$14 | H23: =IF(IF(A23-1-Premissas!$C$16>=0,OFFSET($J$4,A23-1-Premissas!$C$16,0),0)>0,ROUND(IF(A23-1-Premissas!$C$16>=0,OFFSET($J$4,A23-1-Premissas!$C$16,0),0)*10000/Premissas!$C$5*Premissas!$C$15,0),0) | I23: =ROUND(G23*Premissas!$C$6/10000,0) | J23: =ROUND(G23*Premissas!$C$5/10000,0) | K23: =IF(IF(A23-1-Premissas!$C$16>=0,OFFSET($A$4,A23-1-Premissas!$C$16,0)>=Premissas!$C$19,FALSE),ROUND(IF(A23-1-Premissas!$C$16>=0,OFFSET($J$4,A23-1-Premissas!$C$16,0),0)*Premissas!$C$15,0),0) | L23: =ROUND(C23*Premissas!$C$24/12,0) | M23: =ROUND(D23*Premissas!$C$25,0) | N23: =ROUND(E23*Premissas!$C$29+B23*Premissas!$C$30,0) | O23: =K23+L23+M23+N23 | P23: =K23+ROUND(AC23*Premissas!$C$24,0)+M23+N23 | Q23: =ROUND(IF(A23-1-Premissas!$C$21>=0,OFFSET($P$4,A23-1-Premissas!$C$21,0),0)*(1-Premissas!$C$20/100),0) | R23: =ROUND(F23*Premissas!$C$11+N23*Premissas!$C$31/100,0)+ROUND((E23+B23)*Premissas!$C$10,0)+ROUND(Q23*Premissas!$C$8/100,0)+ROUND(Premissas!$C$35+(B23+C23)*Premissas!$C$36,0) | S23: =O23-R23 | T23: =ROUND(O23*Premissas!$C$9/100,0) | U23: =ROUND(AB23*Premissas!$C$33,0) | V23: =Premissas!$C$37+ROUND(Premissas!$C$12*Premissas!$C$38+D23*Premissas!$C$27,0) | W23: =Premissas!$C$39 | X23: =S23-T23-ROUND(Premissas!$C$12*Premissas!$C$38+D23*Premissas!$C$27,0) | Y23: =O23-R23-T23-U23-V23-W23 | Z23: =Q23-R23-T23-U23-V23-W23 | AA23: =AA22+Z23 | AB23: =Premissas!$C$32+(B23+C23)/Premissas!$C$34 | AC23: =D23+AC11*(1-Premissas!$C$26/12)^12
A24: 21 | B24: =B23*(1-Premissas!$C$18/12)+Premissas!$C$12 | C24: =IF($B$2=1,C23*(1-Premissas!$C$26/12)+D24,0) | D24: =IF(AND($B$2=1,A24>=Premissas!$C$23),Premissas!$C$22,0) | E24: =B24*Premissas!$C$28 | F24: =B24*Premissas!$C$13/12*MIN(1,A24/Premissas!$C$17) | G24: =F24*Premissas!$C$14 | H24: =IF(IF(A24-1-Premissas!$C$16>=0,OFFSET($J$4,A24-1-Premissas!$C$16,0),0)>0,ROUND(IF(A24-1-Premissas!$C$16>=0,OFFSET($J$4,A24-1-Premissas!$C$16,0),0)*10000/Premissas!$C$5*Premissas!$C$15,0),0) | I24: =ROUND(G24*Premissas!$C$6/10000,0) | J24: =ROUND(G24*Premissas!$C$5/10000,0) | K24: =IF(IF(A24-1-Premissas!$C$16>=0,OFFSET($A$4,A24-1-Premissas!$C$16,0)>=Premissas!$C$19,FALSE),ROUND(IF(A24-1-Premissas!$C$16>=0,OFFSET($J$4,A24-1-Premissas!$C$16,0),0)*Premissas!$C$15,0),0) | L24: =ROUND(C24*Premissas!$C$24/12,0) | M24: =ROUND(D24*Premissas!$C$25,0) | N24: =ROUND(E24*Premissas!$C$29+B24*Premissas!$C$30,0) | O24: =K24+L24+M24+N24 | P24: =K24+ROUND(AC24*Premissas!$C$24,0)+M24+N24 | Q24: =ROUND(IF(A24-1-Premissas!$C$21>=0,OFFSET($P$4,A24-1-Premissas!$C$21,0),0)*(1-Premissas!$C$20/100),0) | R24: =ROUND(F24*Premissas!$C$11+N24*Premissas!$C$31/100,0)+ROUND((E24+B24)*Premissas!$C$10,0)+ROUND(Q24*Premissas!$C$8/100,0)+ROUND(Premissas!$C$35+(B24+C24)*Premissas!$C$36,0) | S24: =O24-R24 | T24: =ROUND(O24*Premissas!$C$9/100,0) | U24: =ROUND(AB24*Premissas!$C$33,0) | V24: =Premissas!$C$37+ROUND(Premissas!$C$12*Premissas!$C$38+D24*Premissas!$C$27,0) | W24: =Premissas!$C$39 | X24: =S24-T24-ROUND(Premissas!$C$12*Premissas!$C$38+D24*Premissas!$C$27,0) | Y24: =O24-R24-T24-U24-V24-W24 | Z24: =Q24-R24-T24-U24-V24-W24 | AA24: =AA23+Z24 | AB24: =Premissas!$C$32+(B24+C24)/Premissas!$C$34 | AC24: =D24+AC12*(1-Premissas!$C$26/12)^12
A25: 22 | B25: =B24*(1-Premissas!$C$18/12)+Premissas!$C$12 | C25: =IF($B$2=1,C24*(1-Premissas!$C$26/12)+D25,0) | D25: =IF(AND($B$2=1,A25>=Premissas!$C$23),Premissas!$C$22,0) | E25: =B25*Premissas!$C$28 | F25: =B25*Premissas!$C$13/12*MIN(1,A25/Premissas!$C$17) | G25: =F25*Premissas!$C$14 | H25: =IF(IF(A25-1-Premissas!$C$16>=0,OFFSET($J$4,A25-1-Premissas!$C$16,0),0)>0,ROUND(IF(A25-1-Premissas!$C$16>=0,OFFSET($J$4,A25-1-Premissas!$C$16,0),0)*10000/Premissas!$C$5*Premissas!$C$15,0),0) | I25: =ROUND(G25*Premissas!$C$6/10000,0) | J25: =ROUND(G25*Premissas!$C$5/10000,0) | K25: =IF(IF(A25-1-Premissas!$C$16>=0,OFFSET($A$4,A25-1-Premissas!$C$16,0)>=Premissas!$C$19,FALSE),ROUND(IF(A25-1-Premissas!$C$16>=0,OFFSET($J$4,A25-1-Premissas!$C$16,0),0)*Premissas!$C$15,0),0) | L25: =ROUND(C25*Premissas!$C$24/12,0) | M25: =ROUND(D25*Premissas!$C$25,0) | N25: =ROUND(E25*Premissas!$C$29+B25*Premissas!$C$30,0) | O25: =K25+L25+M25+N25 | P25: =K25+ROUND(AC25*Premissas!$C$24,0)+M25+N25 | Q25: =ROUND(IF(A25-1-Premissas!$C$21>=0,OFFSET($P$4,A25-1-Premissas!$C$21,0),0)*(1-Premissas!$C$20/100),0) | R25: =ROUND(F25*Premissas!$C$11+N25*Premissas!$C$31/100,0)+ROUND((E25+B25)*Premissas!$C$10,0)+ROUND(Q25*Premissas!$C$8/100,0)+ROUND(Premissas!$C$35+(B25+C25)*Premissas!$C$36,0) | S25: =O25-R25 | T25: =ROUND(O25*Premissas!$C$9/100,0) | U25: =ROUND(AB25*Premissas!$C$33,0) | V25: =Premissas!$C$37+ROUND(Premissas!$C$12*Premissas!$C$38+D25*Premissas!$C$27,0) | W25: =Premissas!$C$39 | X25: =S25-T25-ROUND(Premissas!$C$12*Premissas!$C$38+D25*Premissas!$C$27,0) | Y25: =O25-R25-T25-U25-V25-W25 | Z25: =Q25-R25-T25-U25-V25-W25 | AA25: =AA24+Z25 | AB25: =Premissas!$C$32+(B25+C25)/Premissas!$C$34 | AC25: =D25+AC13*(1-Premissas!$C$26/12)^12
A26: 23 | B26: =B25*(1-Premissas!$C$18/12)+Premissas!$C$12 | C26: =IF($B$2=1,C25*(1-Premissas!$C$26/12)+D26,0) | D26: =IF(AND($B$2=1,A26>=Premissas!$C$23),Premissas!$C$22,0) | E26: =B26*Premissas!$C$28 | F26: =B26*Premissas!$C$13/12*MIN(1,A26/Premissas!$C$17) | G26: =F26*Premissas!$C$14 | H26: =IF(IF(A26-1-Premissas!$C$16>=0,OFFSET($J$4,A26-1-Premissas!$C$16,0),0)>0,ROUND(IF(A26-1-Premissas!$C$16>=0,OFFSET($J$4,A26-1-Premissas!$C$16,0),0)*10000/Premissas!$C$5*Premissas!$C$15,0),0) | I26: =ROUND(G26*Premissas!$C$6/10000,0) | J26: =ROUND(G26*Premissas!$C$5/10000,0) | K26: =IF(IF(A26-1-Premissas!$C$16>=0,OFFSET($A$4,A26-1-Premissas!$C$16,0)>=Premissas!$C$19,FALSE),ROUND(IF(A26-1-Premissas!$C$16>=0,OFFSET($J$4,A26-1-Premissas!$C$16,0),0)*Premissas!$C$15,0),0) | L26: =ROUND(C26*Premissas!$C$24/12,0) | M26: =ROUND(D26*Premissas!$C$25,0) | N26: =ROUND(E26*Premissas!$C$29+B26*Premissas!$C$30,0) | O26: =K26+L26+M26+N26 | P26: =K26+ROUND(AC26*Premissas!$C$24,0)+M26+N26 | Q26: =ROUND(IF(A26-1-Premissas!$C$21>=0,OFFSET($P$4,A26-1-Premissas!$C$21,0),0)*(1-Premissas!$C$20/100),0) | R26: =ROUND(F26*Premissas!$C$11+N26*Premissas!$C$31/100,0)+ROUND((E26+B26)*Premissas!$C$10,0)+ROUND(Q26*Premissas!$C$8/100,0)+ROUND(Premissas!$C$35+(B26+C26)*Premissas!$C$36,0) | S26: =O26-R26 | T26: =ROUND(O26*Premissas!$C$9/100,0) | U26: =ROUND(AB26*Premissas!$C$33,0) | V26: =Premissas!$C$37+ROUND(Premissas!$C$12*Premissas!$C$38+D26*Premissas!$C$27,0) | W26: =Premissas!$C$39 | X26: =S26-T26-ROUND(Premissas!$C$12*Premissas!$C$38+D26*Premissas!$C$27,0) | Y26: =O26-R26-T26-U26-V26-W26 | Z26: =Q26-R26-T26-U26-V26-W26 | AA26: =AA25+Z26 | AB26: =Premissas!$C$32+(B26+C26)/Premissas!$C$34 | AC26: =D26+AC14*(1-Premissas!$C$26/12)^12
A27: 24 | B27: =B26*(1-Premissas!$C$18/12)+Premissas!$C$12 | C27: =IF($B$2=1,C26*(1-Premissas!$C$26/12)+D27,0) | D27: =IF(AND($B$2=1,A27>=Premissas!$C$23),Premissas!$C$22,0) | E27: =B27*Premissas!$C$28 | F27: =B27*Premissas!$C$13/12*MIN(1,A27/Premissas!$C$17) | G27: =F27*Premissas!$C$14 | H27: =IF(IF(A27-1-Premissas!$C$16>=0,OFFSET($J$4,A27-1-Premissas!$C$16,0),0)>0,ROUND(IF(A27-1-Premissas!$C$16>=0,OFFSET($J$4,A27-1-Premissas!$C$16,0),0)*10000/Premissas!$C$5*Premissas!$C$15,0),0) | I27: =ROUND(G27*Premissas!$C$6/10000,0) | J27: =ROUND(G27*Premissas!$C$5/10000,0) | K27: =IF(IF(A27-1-Premissas!$C$16>=0,OFFSET($A$4,A27-1-Premissas!$C$16,0)>=Premissas!$C$19,FALSE),ROUND(IF(A27-1-Premissas!$C$16>=0,OFFSET($J$4,A27-1-Premissas!$C$16,0),0)*Premissas!$C$15,0),0) | L27: =ROUND(C27*Premissas!$C$24/12,0) | M27: =ROUND(D27*Premissas!$C$25,0) | N27: =ROUND(E27*Premissas!$C$29+B27*Premissas!$C$30,0) | O27: =K27+L27+M27+N27 | P27: =K27+ROUND(AC27*Premissas!$C$24,0)+M27+N27 | Q27: =ROUND(IF(A27-1-Premissas!$C$21>=0,OFFSET($P$4,A27-1-Premissas!$C$21,0),0)*(1-Premissas!$C$20/100),0) | R27: =ROUND(F27*Premissas!$C$11+N27*Premissas!$C$31/100,0)+ROUND((E27+B27)*Premissas!$C$10,0)+ROUND(Q27*Premissas!$C$8/100,0)+ROUND(Premissas!$C$35+(B27+C27)*Premissas!$C$36,0) | S27: =O27-R27 | T27: =ROUND(O27*Premissas!$C$9/100,0) | U27: =ROUND(AB27*Premissas!$C$33,0) | V27: =Premissas!$C$37+ROUND(Premissas!$C$12*Premissas!$C$38+D27*Premissas!$C$27,0) | W27: =Premissas!$C$39 | X27: =S27-T27-ROUND(Premissas!$C$12*Premissas!$C$38+D27*Premissas!$C$27,0) | Y27: =O27-R27-T27-U27-V27-W27 | Z27: =Q27-R27-T27-U27-V27-W27 | AA27: =AA26+Z27 | AB27: =Premissas!$C$32+(B27+C27)/Premissas!$C$34 | AC27: =D27+AC15*(1-Premissas!$C$26/12)^12
... A123: 120 | B123: =B122*(1-Premissas!$C$18/12)+Premissas!$C$12 | C123: =IF($B$2=1,C122*(1-Premissas!$C$26/12)+D123,0) | D123: =IF(AND($B$2=1,A123>=Premissas!$C$23),Premissas!$C$22,0) | E123: =B123*Premissas!$C$28 | F123: =B123*Premissas!$C$13/12*MIN(1,A123/Premissas!$C$17) | G123: =F123*Premissas!$C$14 | H123: =IF(IF(A123-1-Premissas!$C$16>=0,OFFSET($J$4,A123-1-Premissas!$C$16,0),0)>0,ROUND(IF(A123-1-Premissas!$C$16>=0,OFFSET($J$4,A123-1-Premissas!$C$16,0),0)*10000/Premissas!$C$5*Premissas!$C$15,0),0) | I123: =ROUND(G123*Premissas!$C$6/10000,0) | J123: =ROUND(G123*Premissas!$C$5/10000,0) | K123: =IF(IF(A123-1-Premissas!$C$16>=0,OFFSET($A$4,A123-1-Premissas!$C$16,0)>=Premissas!$C$19,FALSE),ROUND(IF(A123-1-Premissas!$C$16>=0,OFFSET($J$4,A123-1-Premissas!$C$16,0),0)*Premissas!$C$15,0),0) | L123: =ROUND(C123*Premissas!$C$24/12,0) | M123: =ROUND(D123*Premissas!$C$25,0) | N123: =ROUND(E123*Premissas!$C$29+B123*Premissas!$C$30,0) | O123: =K123+L123+M123+N123 | P123: =K123+ROUND(AC123*Premissas!$C$24,0)+M123+N123 | Q123: =ROUND(IF(A123-1-Premissas!$C$21>=0,OFFSET($P$4,A123-1-Premissas!$C$21,0),0)*(1-Premissas!$C$20/100),0) | R123: =ROUND(F123*Premissas!$C$11+N123*Premissas!$C$31/100,0)+ROUND((E123+B123)*Premissas!$C$10,0)+ROUND(Q123*Premissas!$C$8/100,0)+ROUND(Premissas!$C$35+(B123+C123)*Premissas!$C$36,0) | S123: =O123-R123 | T123: =ROUND(O123*Premissas!$C$9/100,0) | U123: =ROUND(AB123*Premissas!$C$33,0) | V123: =Premissas!$C$37+ROUND(Premissas!$C$12*Premissas!$C$38+D123*Premissas!$C$27,0) | W123: =Premissas!$C$39 | X123: =S123-T123-ROUND(Premissas!$C$12*Premissas!$C$38+D123*Premissas!$C$27,0) | Y123: =O123-R123-T123-U123-V123-W123 | Z123: =Q123-R123-T123-U123-V123-W123 | AA123: =AA122+Z123 | AB123: =Premissas!$C$32+(B123+C123)/Premissas!$C$34 | AC123: =D123+AC111*(1-Premissas!$C$26/12)^12

Sheet Cons-Híbrido
A1: Cenário conservador · desenho Híbrido (0 = sem contratos institucionais; 1 = com) · valores em CENTAVOS · fórmulas abertas
A2: hybrid | B2: 1
A3: Mês | B3: Financiadores ativos | C3: Contratos inst. ativos | D3: Novos contratos inst. | E3: OSCs ativas | F3: Operações | G3: GMV originado | H3: GMV quitado | I3: Participação de autoria (não é receita) | J3: Taxa registrada | K3: Taxa reconhecida (quitação, regra ativa) | L3: MRR software | M3: Implantação reconhecida | N3: Serviços | O3: RECEITA RECONHECIDA | P3: Faturado | Q3: Recebido (após inadimplência) | R3: COGS | S3: Margem bruta | T3: Tributos | U3: Pessoal | V3: Marketing+CAC | W3: Admin | X3: Margem de contribuição | Y3: EBITDA | Z3: Fluxo de caixa | AA3: Caixa acumulado | AB3: FTE | AC3: Contratos faturados no mês (novos + renovações anuais)
A4: 1 | B4: =0*(1-Premissas!$C$18/12)+Premissas!$C$12 | C4: =IF($B$2=1,0*(1-Premissas!$C$26/12)+D4,0) | D4: =IF(AND($B$2=1,A4>=Premissas!$C$23),Premissas!$C$22,0) | E4: =B4*Premissas!$C$28 | F4: =B4*Premissas!$C$13/12*MIN(1,A4/Premissas!$C$17) | G4: =F4*Premissas!$C$14 | H4: =IF(IF(A4-1-Premissas!$C$16>=0,OFFSET($J$4,A4-1-Premissas!$C$16,0),0)>0,ROUND(IF(A4-1-Premissas!$C$16>=0,OFFSET($J$4,A4-1-Premissas!$C$16,0),0)*10000/Premissas!$C$5*Premissas!$C$15,0),0) | I4: =ROUND(G4*Premissas!$C$6/10000,0) | J4: =ROUND(G4*Premissas!$C$5/10000,0) | K4: =IF(IF(A4-1-Premissas!$C$16>=0,OFFSET($A$4,A4-1-Premissas!$C$16,0)>=Premissas!$C$19,FALSE),ROUND(IF(A4-1-Premissas!$C$16>=0,OFFSET($J$4,A4-1-Premissas!$C$16,0),0)*Premissas!$C$15,0),0) | L4: =ROUND(C4*Premissas!$C$24/12,0) | M4: =ROUND(D4*Premissas!$C$25,0) | N4: =ROUND(E4*Premissas!$C$29+B4*Premissas!$C$30,0) | O4: =K4+L4+M4+N4 | P4: =K4+ROUND(AC4*Premissas!$C$24,0)+M4+N4 | Q4: =ROUND(IF(A4-1-Premissas!$C$21>=0,OFFSET($P$4,A4-1-Premissas!$C$21,0),0)*(1-Premissas!$C$20/100),0) | R4: =ROUND(F4*Premissas!$C$11+N4*Premissas!$C$31/100,0)+ROUND((E4+B4)*Premissas!$C$10,0)+ROUND(Q4*Premissas!$C$8/100,0)+ROUND(Premissas!$C$35+(B4+C4)*Premissas!$C$36,0) | S4: =O4-R4 | T4: =ROUND(O4*Premissas!$C$9/100,0) | U4: =ROUND(AB4*Premissas!$C$33,0) | V4: =Premissas!$C$37+ROUND(Premissas!$C$12*Premissas!$C$38+D4*Premissas!$C$27,0) | W4: =Premissas!$C$39 | X4: =S4-T4-ROUND(Premissas!$C$12*Premissas!$C$38+D4*Premissas!$C$27,0) | Y4: =O4-R4-T4-U4-V4-W4 | Z4: =Q4-R4-T4-U4-V4-W4 | AA4: =Premissas!$C$40+Z4 | AB4: =Premissas!$C$32+(B4+C4)/Premissas!$C$34 | AC4: =D4
A5: 2 | B5: =B4*(1-Premissas!$C$18/12)+Premissas!$C$12 | C5: =IF($B$2=1,C4*(1-Premissas!$C$26/12)+D5,0) | D5: =IF(AND($B$2=1,A5>=Premissas!$C$23),Premissas!$C$22,0) | E5: =B5*Premissas!$C$28 | F5: =B5*Premissas!$C$13/12*MIN(1,A5/Premissas!$C$17) | G5: =F5*Premissas!$C$14 | H5: =IF(IF(A5-1-Premissas!$C$16>=0,OFFSET($J$4,A5-1-Premissas!$C$16,0),0)>0,ROUND(IF(A5-1-Premissas!$C$16>=0,OFFSET($J$4,A5-1-Premissas!$C$16,0),0)*10000/Premissas!$C$5*Premissas!$C$15,0),0) | I5: =ROUND(G5*Premissas!$C$6/10000,0) | J5: =ROUND(G5*Premissas!$C$5/10000,0) | K5: =IF(IF(A5-1-Premissas!$C$16>=0,OFFSET($A$4,A5-1-Premissas!$C$16,0)>=Premissas!$C$19,FALSE),ROUND(IF(A5-1-Premissas!$C$16>=0,OFFSET($J$4,A5-1-Premissas!$C$16,0),0)*Premissas!$C$15,0),0) | L5: =ROUND(C5*Premissas!$C$24/12,0) | M5: =ROUND(D5*Premissas!$C$25,0) | N5: =ROUND(E5*Premissas!$C$29+B5*Premissas!$C$30,0) | O5: =K5+L5+M5+N5 | P5: =K5+ROUND(AC5*Premissas!$C$24,0)+M5+N5 | Q5: =ROUND(IF(A5-1-Premissas!$C$21>=0,OFFSET($P$4,A5-1-Premissas!$C$21,0),0)*(1-Premissas!$C$20/100),0) | R5: =ROUND(F5*Premissas!$C$11+N5*Premissas!$C$31/100,0)+ROUND((E5+B5)*Premissas!$C$10,0)+ROUND(Q5*Premissas!$C$8/100,0)+ROUND(Premissas!$C$35+(B5+C5)*Premissas!$C$36,0) | S5: =O5-R5 | T5: =ROUND(O5*Premissas!$C$9/100,0) | U5: =ROUND(AB5*Premissas!$C$33,0) | V5: =Premissas!$C$37+ROUND(Premissas!$C$12*Premissas!$C$38+D5*Premissas!$C$27,0) | W5: =Premissas!$C$39 | X5: =S5-T5-ROUND(Premissas!$C$12*Premissas!$C$38+D5*Premissas!$C$27,0) | Y5: =O5-R5-T5-U5-V5-W5 | Z5: =Q5-R5-T5-U5-V5-W5 | AA5: =AA4+Z5 | AB5: =Premissas!$C$32+(B5+C5)/Premissas!$C$34 | AC5: =D5
A6: 3 | B6: =B5*(1-Premissas!$C$18/12)+Premissas!$C$12 | C6: =IF($B$2=1,C5*(1-Premissas!$C$26/12)+D6,0) | D6: =IF(AND($B$2=1,A6>=Premissas!$C$23),Premissas!$C$22,0) | E6: =B6*Premissas!$C$28 | F6: =B6*Premissas!$C$13/12*MIN(1,A6/Premissas!$C$17) | G6: =F6*Premissas!$C$14 | H6: =IF(IF(A6-1-Premissas!$C$16>=0,OFFSET($J$4,A6-1-Premissas!$C$16,0),0)>0,ROUND(IF(A6-1-Premissas!$C$16>=0,OFFSET($J$4,A6-1-Premissas!$C$16,0),0)*10000/Premissas!$C$5*Premissas!$C$15,0),0) | I6: =ROUND(G6*Premissas!$C$6/10000,0) | J6: =ROUND(G6*Premissas!$C$5/10000,0) | K6: =IF(IF(A6-1-Premissas!$C$16>=0,OFFSET($A$4,A6-1-Premissas!$C$16,0)>=Premissas!$C$19,FALSE),ROUND(IF(A6-1-Premissas!$C$16>=0,OFFSET($J$4,A6-1-Premissas!$C$16,0),0)*Premissas!$C$15,0),0) | L6: =ROUND(C6*Premissas!$C$24/12,0) | M6: =ROUND(D6*Premissas!$C$25,0) | N6: =ROUND(E6*Premissas!$C$29+B6*Premissas!$C$30,0) | O6: =K6+L6+M6+N6 | P6: =K6+ROUND(AC6*Premissas!$C$24,0)+M6+N6 | Q6: =ROUND(IF(A6-1-Premissas!$C$21>=0,OFFSET($P$4,A6-1-Premissas!$C$21,0),0)*(1-Premissas!$C$20/100),0) | R6: =ROUND(F6*Premissas!$C$11+N6*Premissas!$C$31/100,0)+ROUND((E6+B6)*Premissas!$C$10,0)+ROUND(Q6*Premissas!$C$8/100,0)+ROUND(Premissas!$C$35+(B6+C6)*Premissas!$C$36,0) | S6: =O6-R6 | T6: =ROUND(O6*Premissas!$C$9/100,0) | U6: =ROUND(AB6*Premissas!$C$33,0) | V6: =Premissas!$C$37+ROUND(Premissas!$C$12*Premissas!$C$38+D6*Premissas!$C$27,0) | W6: =Premissas!$C$39 | X6: =S6-T6-ROUND(Premissas!$C$12*Premissas!$C$38+D6*Premissas!$C$27,0) | Y6: =O6-R6-T6-U6-V6-W6 | Z6: =Q6-R6-T6-U6-V6-W6 | AA6: =AA5+Z6 | AB6: =Premissas!$C$32+(B6+C6)/Premissas!$C$34 | AC6: =D6
A7: 4 | B7: =B6*(1-Premissas!$C$18/12)+Premissas!$C$12 | C7: =IF($B$2=1,C6*(1-Premissas!$C$26/12)+D7,0) | D7: =IF(AND($B$2=1,A7>=Premissas!$C$23),Premissas!$C$22,0) | E7: =B7*Premissas!$C$28 | F7: =B7*Premissas!$C$13/12*MIN(1,A7/Premissas!$C$17) | G7: =F7*Premissas!$C$14 | H7: =IF(IF(A7-1-Premissas!$C$16>=0,OFFSET($J$4,A7-1-Premissas!$C$16,0),0)>0,ROUND(IF(A7-1-Premissas!$C$16>=0,OFFSET($J$4,A7-1-Premissas!$C$16,0),0)*10000/Premissas!$C$5*Premissas!$C$15,0),0) | I7: =ROUND(G7*Premissas!$C$6/10000,0) | J7: =ROUND(G7*Premissas!$C$5/10000,0) | K7: =IF(IF(A7-1-Premissas!$C$16>=0,OFFSET($A$4,A7-1-Premissas!$C$16,0)>=Premissas!$C$19,FALSE),ROUND(IF(A7-1-Premissas!$C$16>=0,OFFSET($J$4,A7-1-Premissas!$C$16,0),0)*Premissas!$C$15,0),0) | L7: =ROUND(C7*Premissas!$C$24/12,0) | M7: =ROUND(D7*Premissas!$C$25,0) | N7: =ROUND(E7*Premissas!$C$29+B7*Premissas!$C$30,0) | O7: =K7+L7+M7+N7 | P7: =K7+ROUND(AC7*Premissas!$C$24,0)+M7+N7 | Q7: =ROUND(IF(A7-1-Premissas!$C$21>=0,OFFSET($P$4,A7-1-Premissas!$C$21,0),0)*(1-Premissas!$C$20/100),0) | R7: =ROUND(F7*Premissas!$C$11+N7*Premissas!$C$31/100,0)+ROUND((E7+B7)*Premissas!$C$10,0)+ROUND(Q7*Premissas!$C$8/100,0)+ROUND(Premissas!$C$35+(B7+C7)*Premissas!$C$36,0) | S7: =O7-R7 | T7: =ROUND(O7*Premissas!$C$9/100,0) | U7: =ROUND(AB7*Premissas!$C$33,0) | V7: =Premissas!$C$37+ROUND(Premissas!$C$12*Premissas!$C$38+D7*Premissas!$C$27,0) | W7: =Premissas!$C$39 | X7: =S7-T7-ROUND(Premissas!$C$12*Premissas!$C$38+D7*Premissas!$C$27,0) | Y7: =O7-R7-T7-U7-V7-W7 | Z7: =Q7-R7-T7-U7-V7-W7 | AA7: =AA6+Z7 | AB7: =Premissas!$C$32+(B7+C7)/Premissas!$C$34 | AC7: =D7
A8: 5 | B8: =B7*(1-Premissas!$C$18/12)+Premissas!$C$12 | C8: =IF($B$2=1,C7*(1-Premissas!$C$26/12)+D8,0) | D8: =IF(AND($B$2=1,A8>=Premissas!$C$23),Premissas!$C$22,0) | E8: =B8*Premissas!$C$28 | F8: =B8*Premissas!$C$13/12*MIN(1,A8/Premissas!$C$17) | G8: =F8*Premissas!$C$14 | H8: =IF(IF(A8-1-Premissas!$C$16>=0,OFFSET($J$4,A8-1-Premissas!$C$16,0),0)>0,ROUND(IF(A8-1-Premissas!$C$16>=0,OFFSET($J$4,A8-1-Premissas!$C$16,0),0)*10000/Premissas!$C$5*Premissas!$C$15,0),0) | I8: =ROUND(G8*Premissas!$C$6/10000,0) | J8: =ROUND(G8*Premissas!$C$5/10000,0) | K8: =IF(IF(A8-1-Premissas!$C$16>=0,OFFSET($A$4,A8-1-Premissas!$C$16,0)>=Premissas!$C$19,FALSE),ROUND(IF(A8-1-Premissas!$C$16>=0,OFFSET($J$4,A8-1-Premissas!$C$16,0),0)*Premissas!$C$15,0),0) | L8: =ROUND(C8*Premissas!$C$24/12,0) | M8: =ROUND(D8*Premissas!$C$25,0) | N8: =ROUND(E8*Premissas!$C$29+B8*Premissas!$C$30,0) | O8: =K8+L8+M8+N8 | P8: =K8+ROUND(AC8*Premissas!$C$24,0)+M8+N8 | Q8: =ROUND(IF(A8-1-Premissas!$C$21>=0,OFFSET($P$4,A8-1-Premissas!$C$21,0),0)*(1-Premissas!$C$20/100),0) | R8: =ROUND(F8*Premissas!$C$11+N8*Premissas!$C$31/100,0)+ROUND((E8+B8)*Premissas!$C$10,0)+ROUND(Q8*Premissas!$C$8/100,0)+ROUND(Premissas!$C$35+(B8+C8)*Premissas!$C$36,0) | S8: =O8-R8 | T8: =ROUND(O8*Premissas!$C$9/100,0) | U8: =ROUND(AB8*Premissas!$C$33,0) | V8: =Premissas!$C$37+ROUND(Premissas!$C$12*Premissas!$C$38+D8*Premissas!$C$27,0) | W8: =Premissas!$C$39 | X8: =S8-T8-ROUND(Premissas!$C$12*Premissas!$C$38+D8*Premissas!$C$27,0) | Y8: =O8-R8-T8-U8-V8-W8 | Z8: =Q8-R8-T8-U8-V8-W8 | AA8: =AA7+Z8 | AB8: =Premissas!$C$32+(B8+C8)/Premissas!$C$34 | AC8: =D8
A9: 6 | B9: =B8*(1-Premissas!$C$18/12)+Premissas!$C$12 | C9: =IF($B$2=1,C8*(1-Premissas!$C$26/12)+D9,0) | D9: =IF(AND($B$2=1,A9>=Premissas!$C$23),Premissas!$C$22,0) | E9: =B9*Premissas!$C$28 | F9: =B9*Premissas!$C$13/12*MIN(1,A9/Premissas!$C$17) | G9: =F9*Premissas!$C$14 | H9: =IF(IF(A9-1-Premissas!$C$16>=0,OFFSET($J$4,A9-1-Premissas!$C$16,0),0)>0,ROUND(IF(A9-1-Premissas!$C$16>=0,OFFSET($J$4,A9-1-Premissas!$C$16,0),0)*10000/Premissas!$C$5*Premissas!$C$15,0),0) | I9: =ROUND(G9*Premissas!$C$6/10000,0) | J9: =ROUND(G9*Premissas!$C$5/10000,0) | K9: =IF(IF(A9-1-Premissas!$C$16>=0,OFFSET($A$4,A9-1-Premissas!$C$16,0)>=Premissas!$C$19,FALSE),ROUND(IF(A9-1-Premissas!$C$16>=0,OFFSET($J$4,A9-1-Premissas!$C$16,0),0)*Premissas!$C$15,0),0) | L9: =ROUND(C9*Premissas!$C$24/12,0) | M9: =ROUND(D9*Premissas!$C$25,0) | N9: =ROUND(E9*Premissas!$C$29+B9*Premissas!$C$30,0) | O9: =K9+L9+M9+N9 | P9: =K9+ROUND(AC9*Premissas!$C$24,0)+M9+N9 | Q9: =ROUND(IF(A9-1-Premissas!$C$21>=0,OFFSET($P$4,A9-1-Premissas!$C$21,0),0)*(1-Premissas!$C$20/100),0) | R9: =ROUND(F9*Premissas!$C$11+N9*Premissas!$C$31/100,0)+ROUND((E9+B9)*Premissas!$C$10,0)+ROUND(Q9*Premissas!$C$8/100,0)+ROUND(Premissas!$C$35+(B9+C9)*Premissas!$C$36,0) | S9: =O9-R9 | T9: =ROUND(O9*Premissas!$C$9/100,0) | U9: =ROUND(AB9*Premissas!$C$33,0) | V9: =Premissas!$C$37+ROUND(Premissas!$C$12*Premissas!$C$38+D9*Premissas!$C$27,0) | W9: =Premissas!$C$39 | X9: =S9-T9-ROUND(Premissas!$C$12*Premissas!$C$38+D9*Premissas!$C$27,0) | Y9: =O9-R9-T9-U9-V9-W9 | Z9: =Q9-R9-T9-U9-V9-W9 | AA9: =AA8+Z9 | AB9: =Premissas!$C$32+(B9+C9)/Premissas!$C$34 | AC9: =D9
A10: 7 | B10: =B9*(1-Premissas!$C$18/12)+Premissas!$C$12 | C10: =IF($B$2=1,C9*(1-Premissas!$C$26/12)+D10,0) | D10: =IF(AND($B$2=1,A10>=Premissas!$C$23),Premissas!$C$22,0) | E10: =B10*Premissas!$C$28 | F10: =B10*Premissas!$C$13/12*MIN(1,A10/Premissas!$C$17) | G10: =F10*Premissas!$C$14 | H10: =IF(IF(A10-1-Premissas!$C$16>=0,OFFSET($J$4,A10-1-Premissas!$C$16,0),0)>0,ROUND(IF(A10-1-Premissas!$C$16>=0,OFFSET($J$4,A10-1-Premissas!$C$16,0),0)*10000/Premissas!$C$5*Premissas!$C$15,0),0) | I10: =ROUND(G10*Premissas!$C$6/10000,0) | J10: =ROUND(G10*Premissas!$C$5/10000,0) | K10: =IF(IF(A10-1-Premissas!$C$16>=0,OFFSET($A$4,A10-1-Premissas!$C$16,0)>=Premissas!$C$19,FALSE),ROUND(IF(A10-1-Premissas!$C$16>=0,OFFSET($J$4,A10-1-Premissas!$C$16,0),0)*Premissas!$C$15,0),0) | L10: =ROUND(C10*Premissas!$C$24/12,0) | M10: =ROUND(D10*Premissas!$C$25,0) | N10: =ROUND(E10*Premissas!$C$29+B10*Premissas!$C$30,0) | O10: =K10+L10+M10+N10 | P10: =K10+ROUND(AC10*Premissas!$C$24,0)+M10+N10 | Q10: =ROUND(IF(A10-1-Premissas!$C$21>=0,OFFSET($P$4,A10-1-Premissas!$C$21,0),0)*(1-Premissas!$C$20/100),0) | R10: =ROUND(F10*Premissas!$C$11+N10*Premissas!$C$31/100,0)+ROUND((E10+B10)*Premissas!$C$10,0)+ROUND(Q10*Premissas!$C$8/100,0)+ROUND(Premissas!$C$35+(B10+C10)*Premissas!$C$36,0) | S10: =O10-R10 | T10: =ROUND(O10*Premissas!$C$9/100,0) | U10: =ROUND(AB10*Premissas!$C$33,0) | V10: =Premissas!$C$37+ROUND(Premissas!$C$12*Premissas!$C$38+D10*Premissas!$C$27,0) | W10: =Premissas!$C$39 | X10: =S10-T10-ROUND(Premissas!$C$12*Premissas!$C$38+D10*Premissas!$C$27,0) | Y10: =O10-R10-T10-U10-V10-W10 | Z10: =Q10-R10-T10-U10-V10-W10 | AA10: =AA9+Z10 | AB10: =Premissas!$C$32+(B10+C10)/Premissas!$C$34 | AC10: =D10
